<?xml version="1.0" ?>
<robot name="my_bot">

  <link name="base_link">
    <visual>
      <origin xyz="0 0 0.06" rpy="0 0 0"/>
      <geometry>
        <cylinder radius="0.24" length="0.02"/>
      </geometry>
      <material name="hat_black">
        <color rgba="0.08 0.08 0.08 1.0"/>
      </material>
    </visual>

    <visual>
      <origin xyz="0 0 0.14" rpy="0 0 0"/>
      <geometry>
        <cylinder radius="0.16" length="0.16"/>
      </geometry>
      <material name="hat_black"/>
    </visual>

    <visual>
      <origin xyz="0 0 0.10" rpy="0 0 0"/>
      <geometry>
        <box size="0.34 0.02 0.04"/>
      </geometry>
      <material name="hat_band">
        <color rgba="0.2 0.2 0.2 1.0"/>
      </material>
    </visual>

    <collision>
      <origin xyz="0 0 0.14" rpy="0 0 0"/>
      <geometry>
        <cylinder radius="0.16" length="0.18"/>
      </geometry>
    </collision>

    <inertial>
      <origin xyz="0 0 0.14" rpy="0 0 0"/>
      <mass value="12.0"/>
      <inertia ixx="0.18" ixy="0" ixz="0" iyy="0.18" iyz="0" izz="0.12"/>
    </inertial>
  </link>

  <link name="base_footprint"/>
  <joint name="base_joint" type="fixed">
    <parent link="base_link"/>
    <child link="base_footprint"/>
    <origin xyz="0 0 0" rpy="0 0 0"/>
  </joint>

  <link name="wheel_fl_link">
    <visual>
      <origin xyz="0 0 0" rpy="1.5707963267948966 0 0"/>
      <geometry>
        <cylinder radius="0.055" length="0.03"/>
      </geometry>
      <material name="wheel_gray">
        <color rgba="0.55 0.55 0.55 1.0"/>
      </material>
    </visual>
    <collision>
      <origin xyz="0 0 0" rpy="1.5707963267948966 0 0"/>
      <geometry>
        <cylinder radius="0.055" length="0.03"/>
      </geometry>
    </collision>
    <inertial>
      <origin xyz="0 0 0" rpy="0 0 0"/>
      <mass value="0.15"/>
      <inertia ixx="1e-4" ixy="0" ixz="0" iyy="1e-4" iyz="0" izz="1e-4"/>
    </inertial>
  </link>

  <joint name="wheel_fl_joint" type="continuous">
    <parent link="base_link"/>
    <child link="wheel_fl_link"/>
    <origin xyz="0.16 0.16 0.055" rpy="0 0 0"/>
    <axis xyz="0 1 0"/>
    <dynamics damping="0.0" friction="0.0"/>
  </joint>

  <link name="wheel_fr_link">
    <visual>
      <origin xyz="0 0 0" rpy="1.5707963267948966 0 0"/>
      <geometry>
        <cylinder radius="0.055" length="0.03"/>
      </geometry>
      <material name="wheel_gray"/>
    </visual>
    <collision>
      <origin xyz="0 0 0" rpy="1.5707963267948966 0 0"/>
      <geometry>
        <cylinder radius="0.055" length="0.03"/>
      </geometry>
    </collision>
    <inertial>
      <origin xyz="0 0 0" rpy="0 0 0"/>
      <mass value="0.15"/>
      <inertia ixx="1e-4" ixy="0" ixz="0" iyy="1e-4" iyz="0" izz="1e-4"/>
    </inertial>
  </link>

  <joint name="wheel_fr_joint" type="continuous">
    <parent link="base_link"/>
    <child link="wheel_fr_link"/>
    <origin xyz="0.16 -0.16 0.055" rpy="0 0 0"/>
    <axis xyz="0 1 0"/>
    <dynamics damping="0.0" friction="0.0"/>
  </joint>

  <link name="wheel_rl_link">
    <visual>
      <origin xyz="0 0 0" rpy="1.5707963267948966 0 0"/>
      <geometry>
        <cylinder radius="0.055" length="0.03"/>
      </geometry>
      <material name="wheel_gray"/>
    </visual>
    <collision>
      <origin xyz="0 0 0" rpy="1.5707963267948966 0 0"/>
      <geometry>
        <cylinder radius="0.055" length="0.03"/>
      </geometry>
    </collision>
    <inertial>
      <origin xyz="0 0 0" rpy="0 0 0"/>
      <mass value="0.15"/>
      <inertia ixx="1e-4" ixy="0" ixz="0" iyy="1e-4" iyz="0" izz="1e-4"/>
    </inertial>
  </link>

  <joint name="wheel_rl_joint" type="continuous">
    <parent link="base_link"/>
    <child link="wheel_rl_link"/>
    <origin xyz="-0.16 0.16 0.055" rpy="0 0 0"/>
    <axis xyz="0 1 0"/>
    <dynamics damping="0.02" friction="0.0"/>
  </joint>

  <link name="wheel_rr_link">
    <visual>
      <origin xyz="0 0 0" rpy="1.5707963267948966 0 0"/>
      <geometry>
        <cylinder radius="0.055" length="0.03"/>
      </geometry>
      <material name="wheel_gray"/>
    </visual>
    <collision>
      <origin xyz="0 0 0" rpy="1.5707963267948966 0 0"/>
      <geometry>
        <cylinder radius="0.055" length="0.03"/>
      </geometry>
    </collision>
    <inertial>
      <origin xyz="0 0 0" rpy="0 0 0"/>
      <mass value="0.15"/>
      <inertia ixx="1e-4" ixy="0" ixz="0" iyy="1e-4" iyz="0" izz="1e-4"/>
    </inertial>
  </link>

  <joint name="wheel_rr_joint" type="continuous">
    <parent link="base_link"/>
    <child link="wheel_rr_link"/>
    <origin xyz="-0.16 -0.16 0.055" rpy="0 0 0"/>
    <axis xyz="0 1 0"/>
    <dynamics damping="0.02" friction="0.0"/>
  </joint>

  <joint name="lidar_joint" type="fixed">
    <parent link="base_link"/>
    <child link="lidar_link"/>
    <origin xyz="0.2 0 0.22" rpy="0 0 0"/>
  </joint>

  <link name="lidar_link">
    <visual>
      <origin xyz="0 0 0" rpy="0 0 0"/>
      <geometry>
        <cylinder radius="0.05" length="0.04"/>
      </geometry>
      <material name="black_lidar"/>
    </visual>
    <collision>
      <geometry>
        <cylinder radius="0.05" length="0.04"/>
      </geometry>
    </collision>
    <inertial>
      <mass value="0.1"/>
      <inertia ixx="0.0001" ixy="0" ixz="0" iyy="0.0001" iyz="0" izz="0.0001"/>
    </inertial>
  </link>

  <joint name="camera_joint" type="fixed">
    <parent link="base_link"/>
    <child link="camera_link"/>
    <origin xyz="0.3 0 0.08" rpy="0 0 0"/>
  </joint>

  <link name="camera_link">
    <visual>
      <origin xyz="0 0 0" rpy="0 0 0"/>
      <geometry>
        <box size="0.03 0.1 0.03"/> </geometry>
      <material name="camera_gray"/>
    </visual>
    <collision>
      <geometry>
        <box size="0.03 0.1 0.03"/>
      </geometry>
    </collision>
    <inertial>
      <mass value="0.05"/>
      <inertia ixx="0.0001" ixy="0" ixz="0" iyy="0.0001" iyz="0" izz="0.0001"/>
    </inertial>
  </link>

  <joint name="imu_joint" type="fixed">
    <parent link="base_link"/>
    <child link="imu_link"/>
    <origin xyz="0 0 0.1" rpy="0 0 0"/>
  </joint>

  <link name="imu_link">
    <visual>
      <geometry><box size="0.02 0.02 0.02"/></geometry>
      <material name="black"/>
    </visual>
    <collision>
      <geometry><box size="0.02 0.02 0.02"/></geometry>
    </collision>
    <inertial>
      <mass value="0.01"/>
      <inertia ixx="0.0001" ixy="0" ixz="0" iyy="0.0001" iyz="0" izz="0.0001"/>
    </inertial>
  </link>

  <gazebo>
    <plugin filename="gz-sim-diff-drive-system" name="gz::sim::systems::DiffDrive">
      <left_joint>wheel_fl_joint</left_joint>
      <right_joint>wheel_fr_joint</right_joint>

      <wheel_separation>0.32</wheel_separation>
      <wheel_radius>0.055</wheel_radius>

      <topic>/cmd_vel</topic>
      <odom_topic>/odom</odom_topic>
      <tf_topic>/tf</tf_topic>
      <frame_id>odom</frame_id>
      <child_frame_id>base_link</child_frame_id>
      <odom_publish_frequency>50</odom_publish_frequency>

      <max_angular_velocity>6.0</max_angular_velocity>
      <max_angular_acceleration>35.0</max_angular_acceleration>
      <max_linear_velocity>1.5</max_linear_velocity>
      <max_linear_acceleration>5.0</max_linear_acceleration>
    </plugin>

    <plugin filename="gz-sim-imu-system" name="gz::sim::systems::Imu">
    </plugin>
  </gazebo>

  <gazebo reference="imu_link">
    <sensor name="imu_sensor" type="imu">
      <always_on>1</always_on>
      <update_rate>100</update_rate> <visualize>true</visualize>
      <topic>/imu</topic>
      <gz_frame_id>imu_link</gz_frame_id>
    </sensor>
    <material>Gazebo/Black</material>
  </gazebo>

  <gazebo reference="lidar_link">
    <sensor name="lidar" type="gpu_lidar">
      <pose>0 0 0 0 0 0</pose>
      <topic>/scan</topic> 
      <update_rate>10</update_rate>
      <gz_frame_id>lidar_link</gz_frame_id>
      <visualize>false</visualize>
      <ray>
        <scan>
          <horizontal>
            <samples>180</samples>
            <resolution>1</resolution>
            <min_angle>-3.14159</min_angle>
            <max_angle>3.14159</max_angle>
          </horizontal>
        </scan>
        <range>
          <min>0.15</min>
          <max>10.0</max>
        </range>
      </ray>
      <always_on>1</always_on>
    </sensor>
  </gazebo>

  <gazebo reference="camera_link">
    <sensor name="depth_camera" type="depth_camera">
      <pose>0 0 0 0 0 0</pose>
      <update_rate>6</update_rate>
      <topic>/depth_camera</topic>
      <gz_frame_id>camera_link</gz_frame_id>
      <always_on>1</always_on>
      <visualize>true</visualize> <camera>
        <horizontal_fov>1.51843645</horizontal_fov>
        <image>
          <width>848</width>
          <height>480</height>
          <format>R_FLOAT32</format>
        </image>
        <clip>
          <near>0.1</near>
          <far>10</far>
        </clip>
        <lens>
          <intrinsics>
            <fx>421.61578369140625</fx>
            <fy>421.61578369140625</fy>
            <cx>422.2854309082031</cx>
            <cy>236.57237243652344</cy>
            <s>0</s>
          </intrinsics>
        </lens>
      </camera>
    </sensor>
  </gazebo>

  <gazebo reference="wheel_fl_link">
    <mu1>2.0</mu1>
    <mu2>2.0</mu2>
  </gazebo>

  <gazebo reference="wheel_fr_link">
    <mu1>2.0</mu1>
    <mu2>2.0</mu2>
  </gazebo>

  <gazebo reference="wheel_rl_link">
    <mu1>0.02</mu1>
    <mu2>0.02</mu2>
  </gazebo>

  <gazebo reference="wheel_rr_link">
    <mu1>0.02</mu1>
    <mu2>0.02</mu2>
  </gazebo>

  <gazebo reference="base_link">
    <mu1>0.2</mu1>
    <mu2>0.2</mu2>
  </gazebo>

</robot>